
Ready
Joining VC
Ignoring exception in command None:
discord.ext.commands.errors.CommandNotFound: Command "doit" is not found
Ignoring exception in command join:
Traceback (most recent call last):
  File "/home/lua/.local/lib/python3.10/site-packages/discord/ext/commands/core.py", line 85, in wrapped
    ret = await coro(*args, **kwargs)
  File "/home/lua/Documents/Code/gpt3-bot/main.py", line 89, in join
    await channel.connect()
  File "/home/lua/.local/lib/python3.10/site-packages/discord/abc.py", line 1274, in connect
    raise ClientException('Already connected to a voice channel.')
discord.errors.ClientException: Already connected to a voice channel.
The above exception was the direct cause of the following exception:
Traceback (most recent call last):
  File "/home/lua/.local/lib/python3.10/site-packages/discord/ext/commands/bot.py", line 939, in invoke
    await ctx.command.invoke(ctx)
  File "/home/lua/.local/lib/python3.10/site-packages/discord/ext/commands/core.py", line 863, in invoke
    await injected(*ctx.args, **ctx.kwargs)
  File "/home/lua/.local/lib/python3.10/site-packages/discord/ext/commands/core.py", line 94, in wrapped
    raise CommandInvokeError(exc) from exc
discord.ext.commands.errors.CommandInvokeError: Command raised an exception: ClientException: Already connected to a voice channel.
Atleast here
Joining VC
[38m[48m[mp3 @ 0x5616dfff65c0] Estimating duration from bitrate, this may be inaccurate
Atleast here
[38m[48m[mp3 @ 0x556d832e45c0] Estimating duration from bitrate, this may be inaccurate
Atleast here
awww. ANYWAYS I
Ignoring exception in command gen:
Traceback (most recent call last):
  File "/home/lua/.local/lib/python3.10/site-packages/discord/ext/commands/core.py", line 85, in wrapped
    ret = await coro(*args, **kwargs)
  File "/home/lua/Documents/Code/gpt3-bot/main.py", line 138, in gen
    await ctx.message.channel.send(response)
  File "/home/lua/.local/lib/python3.10/site-packages/discord/abc.py", line 1065, in send
    data = await state.http.send_message(channel.id, content, tts=tts, embed=embed,
  File "/home/lua/.local/lib/python3.10/site-packages/discord/http.py", line 192, in request
    async with self.__session.request(method, url, **kwargs) as r:
  File "/home/lua/.local/lib/python3.10/site-packages/aiohttp/client.py", line 1117, in __aenter__
    self._resp = await self._coro
  File "/home/lua/.local/lib/python3.10/site-packages/aiohttp/client.py", line 381, in _request
    raise RuntimeError("Session is closed")
RuntimeError: Session is closed
The above exception was the direct cause of the following exception:
Traceback (most recent call last):
  File "/home/lua/.local/lib/python3.10/site-packages/discord/ext/commands/bot.py", line 939, in invoke
    await ctx.command.invoke(ctx)
  File "/home/lua/.local/lib/python3.10/site-packages/discord/ext/commands/core.py", line 863, in invoke
    await injected(*ctx.args, **ctx.kwargs)
  File "/home/lua/.local/lib/python3.10/site-packages/discord/ext/commands/core.py", line 94, in wrapped
    raise CommandInvokeError(exc) from exc
discord.ext.commands.errors.CommandInvokeError: Command raised an exception: RuntimeError: Session is closed