
Ready
Joining VC
/home/lua/.local/lib/python3.10/site-packages/discord/player.py:660: RuntimeWarning: coroutine 'DiscordVoiceWebSocket.speak' was never awaited
  log.info("Speaking call in player failed: %s", e)
RuntimeWarning: Enable tracemalloc to get the object allocation traceback
Exception in voice thread Thread-18
Traceback (most recent call last):
  File "/home/lua/.local/lib/python3.10/site-packages/discord/player.py", line 603, in run
    self._do_run()
  File "/home/lua/.local/lib/python3.10/site-packages/discord/player.py", line 596, in _do_run
    play_audio(data, encode=not self.source.is_opus())
  File "/home/lua/.local/lib/python3.10/site-packages/discord/voice_client.py", line 638, in send_audio_packet
    self.socket.sendto(packet, (self.endpoint_ip, self.voice_port))
OSError: [Errno 9] Bad file descriptor