
Ready
Atleast here
Ignoring exception in command gen:
Traceback (most recent call last):
  File "/home/lua/.local/lib/python3.10/site-packages/discord/ext/commands/core.py", line 85, in wrapped
    ret = await coro(*args, **kwargs)
  File "/home/lua/Documents/Code/gpt3-bot/main.py", line 154, in gen
    tts = gTTS(response, lang="se", slow=False)
  File "/home/lua/.local/lib/python3.10/site-packages/gtts/tts.py", line 151, in __init__
    raise ValueError("Language not supported: %s" % lang)
ValueError: Language not supported: se
The above exception was the direct cause of the following exception:
Traceback (most recent call last):
  File "/home/lua/.local/lib/python3.10/site-packages/discord/ext/commands/bot.py", line 939, in invoke
    await ctx.command.invoke(ctx)
  File "/home/lua/.local/lib/python3.10/site-packages/discord/ext/commands/core.py", line 863, in invoke
    await injected(*ctx.args, **ctx.kwargs)
  File "/home/lua/.local/lib/python3.10/site-packages/discord/ext/commands/core.py", line 94, in wrapped
    raise CommandInvokeError(exc) from exc
discord.ext.commands.errors.CommandInvokeError: Command raised an exception: ValueError: Language not supported: se