
Ready
Ignoring exception in command gen:
Traceback (most recent call last):
  File "/home/lua/.local/lib/python3.10/site-packages/discord/ext/commands/core.py", line 85, in wrapped
    ret = await coro(*args, **kwargs)
  File "/home/lua/Documents/Code/gpt3-bot/main.py", line 131, in gen
    await ResetAudio(ctx)
  File "/home/lua/Documents/Code/gpt3-bot/main.py", line 120, in ResetAudio
    channel = author.voice.channel
AttributeError: 'NoneType' object has no attribute 'channel'
The above exception was the direct cause of the following exception:
Traceback (most recent call last):
  File "/home/lua/.local/lib/python3.10/site-packages/discord/ext/commands/bot.py", line 939, in invoke
    await ctx.command.invoke(ctx)
  File "/home/lua/.local/lib/python3.10/site-packages/discord/ext/commands/core.py", line 863, in invoke
    await injected(*ctx.args, **ctx.kwargs)
  File "/home/lua/.local/lib/python3.10/site-packages/discord/ext/commands/core.py", line 94, in wrapped
    raise CommandInvokeError(exc) from exc
discord.ext.commands.errors.CommandInvokeError: Command raised an exception: AttributeError: 'NoneType' object has no attribute 'channel'
Atleast here
Joining VC
Atleast here
[38m[48m[mp3 @ 0x555c2ff685c0] Estimating duration from bitrate, this may be inaccurate
Atleast here
Ignoring exception in command gen:
Traceback (most recent call last):
  File "/home/lua/.local/lib/python3.10/site-packages/discord/ext/commands/core.py", line 85, in wrapped
    ret = await coro(*args, **kwargs)
  File "/home/lua/Documents/Code/gpt3-bot/main.py", line 131, in gen
    await ResetAudio(ctx)
  File "/home/lua/Documents/Code/gpt3-bot/main.py", line 120, in ResetAudio
    channel = author.voice.channel
AttributeError: 'NoneType' object has no attribute 'channel'
The above exception was the direct cause of the following exception:
Traceback (most recent call last):
  File "/home/lua/.local/lib/python3.10/site-packages/discord/ext/commands/bot.py", line 939, in invoke
    await ctx.command.invoke(ctx)
  File "/home/lua/.local/lib/python3.10/site-packages/discord/ext/commands/core.py", line 863, in invoke
    await injected(*ctx.args, **ctx.kwargs)
  File "/home/lua/.local/lib/python3.10/site-packages/discord/ext/commands/core.py", line 94, in wrapped
    raise CommandInvokeError(exc) from exc
discord.ext.commands.errors.CommandInvokeError: Command raised an exception: AttributeError: 'NoneType' object has no attribute 'channel'
Ignoring exception in command None:
discord.ext.commands.errors.CommandNotFound: Command "huh?" is not found
Joining VC
Atleast here
Ignoring exception in command gen:
Traceback (most recent call last):
  File "/home/lua/.local/lib/python3.10/site-packages/discord/ext/commands/core.py", line 85, in wrapped
    ret = await coro(*args, **kwargs)
  File "/home/lua/Documents/Code/gpt3-bot/main.py", line 131, in gen
    await ResetAudio(ctx)
  File "/home/lua/Documents/Code/gpt3-bot/main.py", line 120, in ResetAudio
    channel = author.voice.channel
AttributeError: 'NoneType' object has no attribute 'channel'
The above exception was the direct cause of the following exception:
Traceback (most recent call last):
  File "/home/lua/.local/lib/python3.10/site-packages/discord/ext/commands/bot.py", line 939, in invoke
    await ctx.command.invoke(ctx)
  File "/home/lua/.local/lib/python3.10/site-packages/discord/ext/commands/core.py", line 863, in invoke
    await injected(*ctx.args, **ctx.kwargs)
  File "/home/lua/.local/lib/python3.10/site-packages/discord/ext/commands/core.py", line 94, in wrapped
    raise CommandInvokeError(exc) from exc
discord.ext.commands.errors.CommandInvokeError: Command raised an exception: AttributeError: 'NoneType' object has no attribute 'channel'
Joining VC
Atleast here
[38m[48m[mp3 @ 0x557bd2dea5c0] Estimating duration from bitrate, this may be inaccurate
 got through the if not
en
Atleast here
Ignoring exception in command gen:
Traceback (most recent call last):
  File "/home/lua/.local/lib/python3.10/site-packages/discord/ext/commands/core.py", line 85, in wrapped
    ret = await coro(*args, **kwargs)
  File "/home/lua/Documents/Code/gpt3-bot/main.py", line 131, in gen
    await ResetAudio(ctx)
  File "/home/lua/Documents/Code/gpt3-bot/main.py", line 121, in ResetAudio
    await channel.connect()
  File "/home/lua/.local/lib/python3.10/site-packages/discord/abc.py", line 1274, in connect
    raise ClientException('Already connected to a voice channel.')
discord.errors.ClientException: Already connected to a voice channel.
The above exception was the direct cause of the following exception:
Traceback (most recent call last):
  File "/home/lua/.local/lib/python3.10/site-packages/discord/ext/commands/bot.py", line 939, in invoke
    await ctx.command.invoke(ctx)
  File "/home/lua/.local/lib/python3.10/site-packages/discord/ext/commands/core.py", line 863, in invoke
    await injected(*ctx.args, **ctx.kwargs)
  File "/home/lua/.local/lib/python3.10/site-packages/discord/ext/commands/core.py", line 94, in wrapped
    raise CommandInvokeError(exc) from exc
discord.ext.commands.errors.CommandInvokeError: Command raised an exception: ClientException: Already connected to a voice channel.
Atleast here
[38m[48m[mp3 @ 0x5595105b05c0] Estimating duration from bitrate, this may be inaccurate
Atleast here
[38m[48m[mp3 @ 0x55a4c42d35c0] Estimating duration from bitrate, this may be inaccurate
Atleast here
[38m[48m[mp3 @ 0x56329055d5c0] Estimating duration from bitrate, this may be inaccurate
Atleast here
[38m[48m[mp3 @ 0x55e56c7e95c0] Estimating duration from bitrate, this may be inaccurate
Atleast here
[38m[48m[mp3 @ 0x561b316d45c0] Estimating duration from bitrate, this may be inaccurate
Atleast here
Ignoring exception in command gen:
Traceback (most recent call last):
  File "/home/lua/.local/lib/python3.10/site-packages/discord/ext/commands/core.py", line 85, in wrapped
    ret = await coro(*args, **kwargs)
  File "/home/lua/Documents/Code/gpt3-bot/main.py", line 131, in gen
    await ResetAudio(ctx)
  File "/home/lua/Documents/Code/gpt3-bot/main.py", line 120, in ResetAudio
    channel = author.voice.channel
AttributeError: 'NoneType' object has no attribute 'channel'
The above exception was the direct cause of the following exception:
Traceback (most recent call last):
  File "/home/lua/.local/lib/python3.10/site-packages/discord/ext/commands/bot.py", line 939, in invoke
    await ctx.command.invoke(ctx)
  File "/home/lua/.local/lib/python3.10/site-packages/discord/ext/commands/core.py", line 863, in invoke
    await injected(*ctx.args, **ctx.kwargs)
  File "/home/lua/.local/lib/python3.10/site-packages/discord/ext/commands/core.py", line 94, in wrapped
    raise CommandInvokeError(exc) from exc
discord.ext.commands.errors.CommandInvokeError: Command raised an exception: AttributeError: 'NoneType' object has no attribute 'channel'