
Ready
Joining VC
Ignoring exception in command None:
discord.ext.commands.errors.CommandNotFound: Command "doit" is not found
Atleast here
[38m[48m[mp3 @ 0x55db08f3e5c0] Estimating duration from bitrate, this may be inaccurate
[38m[48m[mp3 @ 0x562980bd55c0] Estimating duration from bitrate, this may be inaccurate
Atleast here
Atleast here
[38m[48m[mp3 @ 0x564dd404e5c0] Estimating duration from bitrate, this may be inaccurate
Joining VC
Atleast here
Ignoring exception in command join:
Traceback (most recent call last):
  File "/home/lua/.local/lib/python3.10/site-packages/discord/ext/commands/core.py", line 85, in wrapped
    ret = await coro(*args, **kwargs)
  File "/home/lua/Documents/Code/gpt3-bot/main.py", line 114, in join
    await channel.connect()
  File "/home/lua/.local/lib/python3.10/site-packages/discord/abc.py", line 1274, in connect
    raise ClientException('Already connected to a voice channel.')
discord.errors.ClientException: Already connected to a voice channel.
The above exception was the direct cause of the following exception:
Traceback (most recent call last):
  File "/home/lua/.local/lib/python3.10/site-packages/discord/ext/commands/bot.py", line 939, in invoke
    await ctx.command.invoke(ctx)
  File "/home/lua/.local/lib/python3.10/site-packages/discord/ext/commands/core.py", line 863, in invoke
    await injected(*ctx.args, **ctx.kwargs)
  File "/home/lua/.local/lib/python3.10/site-packages/discord/ext/commands/core.py", line 94, in wrapped
    raise CommandInvokeError(exc) from exc
discord.ext.commands.errors.CommandInvokeError: Command raised an exception: ClientException: Already connected to a voice channel.
Joining VC